<h1>Tratamento de erros no C# - Exceptions</h1>



Componentes de software podem ter problemas durante a execução e gerar erros como:

- Terminar o programa;
- Retornar uma mensagem de erro indicando uma falha;
- Retornar e ignorar o problema;
- Chamar um método para tratar o erro, entre outras.

Os problemas mais comumente encontrados são:

- Falha na aquisição de um recurso (new, open...);
- Tentativa de fazer algo impossível (divisão por zero, índice de um array inválido...);
- Outras condições inválidas (lista vazia, overflow...).

Para contornar estes empecilhos, utilizamos o recurso chamado **Exceções (Exceptions)**.

<br />

<h2>1. Exceptions</h2>



As **Exceções** (Exceptions) são uma indicação de um problema que ocorre durante a execução de um programa, ou seja, são eventos que interrompem o fluxo normal de processamento de uma classe causando um erro na aplicação. 

Na Linguagem C#, é possível tratar as exceções, que normalmente interromperiam a execução da aplicação, de forma que o programa continue funcionando ou termine de forma elegante, tornando o código muito mais robusto e confiável.

As Exceções na Linguagem C# são Objetos criados a partir de Classes especiais, que são “disparados” quando ocorrem condições excepcionais durante a execução do código. 

<h3>1.1 Tipos de erros</h2>
Os erros que acontecem nas aplicações C# estão classificados em 3 categorias:

1. **Erros de lógica:** Esta categoria abrange erros na construção do Algoritmo. Este tipo de erro devem ser corrigidos pelo programador

	**Exemplos:** Limites do vetor ultrapassados, divisão por zero, entre outros;

2. **Erros devido a condições do ambiente de execução:** Esta categoria abrange erros na infraestrutura onde a aplicação está sendo executada. Este tipo de erro foge do controle da pessoa desenvolvedora, mas podem ser contornados em tempo de execução;

	**Exemplos:** arquivo não encontrado, rede fora do ar, entre outros;

3. **Erros graves:** São erros que simplesmente travam o sistema e não há nada o que fazer. Este tipo de erro foge do controle da pessoa desenvolvedora e não podem ser contornados;

	**Exemplos:** falta de memória, erro interno do C#, entre outros.

As Exceções tem como foco principal tratar os erros do tipo 1, ou seja, erros de lógica, como veremos no exemplo abaixo:

<br />

<img src="https://i.imgur.com/bm8Jxxm.png" title="source: imgur.com" width="4%"/>**Exemplo 01 - Divisão entre 2 números inteiros:** 

```c#
using System.Runtime.ConstrainedExecution;

namespace exceptions_01
{
    internal class Program
    {
        static void Main(string[] args)
        {
            int dividendo = 0;
            int divisor = 0;

            Console.WriteLine("Digite o Dividendo: ");
            dividendo = Convert.ToInt32(Console.ReadLine());

            Console.WriteLine("Digite o Divisor: ");
            divisor = Convert.ToInt32(Console.ReadLine());

            Dividir(dividendo, divisor);
        }

        public static void Dividir(int dividendo, int divisor)
        {
            Console.WriteLine("Divisão = " + (dividendo / divisor));
        }

    }
}
```

O código acima, é um programa simples, que recebe 2 números inteiros e chama um método chamado dividir(), que fará a divisão entre estes 2 número. Execute o código acima e digite os valores 10 e 0.

<img src="https://i.imgur.com/V2ReOnx.png" title="source: imgur.com" width="3%"/>**Resultado do Algoritmo:**

<div align="center"><img src="https://i.imgur.com/nW6eFDq.png" title="source: imgur.com" /></div>

Na imagem acima, vemos que foi disparada uma exceção: **DivideByZeroException** (indicado por uma seta verde), informando que aconteceu algum erro em uma operação aritmética (cálculo matemático) e na sequência o programa é finalizado sem dar a oportunidade de contornar o erro. No exemplo acima, a exceção indica que não é possível efetuar a divisão de um número por zero.

Execute o código novamente e experimente inserir uma string ao invés de um numero no segundo valor. 

<img src="https://i.imgur.com/V2ReOnx.png" title="source: imgur.com" width="3%"/>**Resultado do Algoritmo:**

<div align="center"><img src="https://i.imgur.com/W0VruvS.png" title="source: imgur.com" /></div>

Na imagem acima, vemos que desta vez foi disparada uma outra exceção: **FormatException** (indicado por uma seta verde), informando que aconteceu algum erro na entrada de dados da aplicação e na sequência o programa é finalizado sem dar a oportunidade de contornar o erro. No exemplo acima, a exceção indica que o Método de conversão  tentou converter a string em número inteiro conseguiu, ou seja, estava aguardando por um número inteiro e recebeu uma string.

<br />

<div align="left"><img src="https://i.imgur.com/JACNZiR.png" title="source: imgur.com" width="25px"/> <a href="" target="_blank"><b>Código fonte: Exemplo 01</b></a></div>

<br />

Quando uma exceção é lançada sem nenhum tipo de tratamento, ela interrompe o **fluxo normal** do programa, como vimos nos 2 exemplos acima. Se o método onde o erro aconteceu não capturar a exceção, ela será **propagada** para o método que chamar esse método e assim por diante. Se **ninguém** capturar a exceção, ela causará o término da aplicação. Agora se em algum lugar ela for capturada, **o controle da aplicação pode ser recuperado**.

Um bom **Sistema de Tratamento de Exceções** procura sempre atender a 3 princípios fundamentais: 

- Se antecipar aos problemas (uma das tarefas da pessoa desenvolvedora);
- Reverter situações de erro que podem ser revertidas;
- Buscar a **Solução ideal** para o tratamento de problemas de forma isolada do código principal.

Com o tratamento de exceções, o programa captura e trata o erro, isto é, lida com a exceção. Para capturar e lidar com as exceções o C# utiliza a estrutura **try-catch-finally**.

<br />

<h2>2. Estrutura try-catch-finally</h2>

A estrutura **try-catch-finally** é utilizada pelo C# para capturar e tratar um erro ou exceção. Ela é composta por 3 estruturas básicas:

- **try:** é usada para indicar um bloco de código que possa lançar (throw) uma exceção. Caso ocorra uma exceção em algum ponto, o restante do código contido no bloco <em>try</em> não será executado. O bloco <em>try</em> não pode ser declarado sozinho, portanto, precisa estar seguido de um ou vários blocos <em>catch</em> e/ou de um bloco <em>finally</em>.
- **catch:** serve para manipular as exceções, ou seja, tratar o erro. Esse bloco será executado somente se o bloco <em>try</em> apresentar alguma exceção. Numa estrutura try-catch-finally você pode criar um ou mais blocos <em>catch</em>, porém, será executado apenas o primeiro bloco que identificar a exceção.
- **finally:** é um bloco opcional, mas caso seja construído, quase sempre será executado, a menos que seja forçada sua parada, por exemplo, com um System.exit(0), no catch (finalizar a aplicação independente do que estiver sendo processado). Dentro do bloco finally, poderá conter outros blocos try-catch, bem como outro <em>finally</em>. Geralmente utilizamos o bloco finally quando precisamos executar algum código independente se ocorrer a exception ou não.

Na imagem abaixo, vemos a sintaxe da estrutura try-catch-finally dentro do código C#:

<div align="center"><img src="https://i.imgur.com/Uwvqs3q.png" title="source: imgur.com" /></div>

O **Bloco try** contém o código que pode lançar (throw) uma exceção. Ele consiste na palavra – chave try seguida por um bloco de código entre chaves.

O **Bloco Catch** captura e trata uma exceção. Ele começa com a palavra-chave catch. Dentro dos parênteses deve ser inserido o parâmetro de exceção, que identifica o tipo da exceção, ou seja, um Objeto da classe ou subclasse da possível exceção. O bloco de código entre as chaves será executado quando uma exceção do tipo indicado no parâmetro ocorre, ou seja, o que fazer em caso de erro.

O **Bloco Finally** se for construído, quase sempre será executado. Geralmente ele contém código de liberação de recursos do sistema. **Exemplo:** finalizar a conexão com uma Banco de dados

Na imagem abaixo, vemos a sintaxe da estrutura try-catch-finally dentro do código C#:

<div align="center"><img src="https://i.imgur.com/hORZemU.png" title="source: imgur.com" /></div>

<br />

<h3>2.1 O comando de Saída Console.Error.WriteLine()</h3>

O comando de Saída **Console.Error.WriteLine()** funciona da mesma forma que o comando de Saída Console.WriteLine(). A principal diferença é que este comando é usado principalmente para exibir os erros de exceção no console. 

Vamos implementar o tratamento de exceções no **Exemplo 01**:

<br />

<img src="https://i.imgur.com/bm8Jxxm.png" title="source: imgur.com" width="4%"/>**Exemplo 02 - Divisão entre 2 números inteiros com tratamento de exceções:** 

```c#
using System.Runtime.ConstrainedExecution;

namespace exceptions_02
{
    internal class Program
    {
        static void Main(string[] args)
        {
            int dividendo = 0;
            int divisor = 0;
            bool loop = true;

            do
            {

                try
                {
                    Console.WriteLine("Digite o Dividendo: ");
                    dividendo = Convert.ToInt32(Console.ReadLine());

                    Console.WriteLine("Digite o Divisor: ");
                    divisor = Convert.ToInt32(Console.ReadLine());

                    Dividir(dividendo, divisor);

                    loop = false;

                }
                catch (FormatException e)
                {
                    Console.Error.WriteLine("\nExceção: " + e);
                    Console.WriteLine("\nDigite valores inteiros!");
                }
                catch (DivideByZeroException e)
                {
                    Console.Error.WriteLine("\nExceção: " + e);
                    Console.WriteLine("\nDigite Numeros inteiros positivos!");
                }
                finally
                {
                    Console.WriteLine("\nSempre serei executada!\n");
                }

            } while (loop);
        }

        public static void Dividir(int dividendo, int divisor)
        {
            Console.WriteLine("Divisão = " + (dividendo / divisor));
        }
    }
}
```

Execute o código acima e digite os valores 10 e 0, novamente.

<img src="https://i.imgur.com/V2ReOnx.png" title="source: imgur.com" width="3%"/>**Resultado do Algoritmo:**

<div align="center"><img src="https://i.imgur.com/hBAN7qK.png" title="source: imgur.com" /></div>

<br />

Observe na imagem acima que a exceção: **DivideByZeroException**  (indicado pela seta rosa), foi disparada, mas desta vez foi exibida uma mensagem personalizada de alerta sobre o erro (indicada pela seta amarela). Como implementamos o bloco **finally**, também será exibida a mensagem criada dentro do bloco (indicada pela seta azul) e o programa será reiniciado (seta verde), solicitando uma nova entrada de dados. 

<br />

| <img src="https://i.imgur.com/hOgWvSc.png" title="source: imgur.com" width="100px"/> | <div align="left"> **IMPORTANTE:** *Para ocultar a Exceção que foi disparada (linha indicada pela seta rosa), e exibir apenas a mensagem personalizada, basta não exibir no console o conteúdo da variável e, que armazena a Exceção capturada.* </div> |
| ------------------------------------------------------------ | ------------------------------------------------------------ |

<br />

Experimente inserir uma string ao invés de um numero no segundo valor. 

<img src="https://i.imgur.com/V2ReOnx.png" title="source: imgur.com" width="3%"/>**Resultado do Algoritmo:**

<div align="center"><img src="https://i.imgur.com/jMXNLnf.png" title="source: imgur.com" /></div>

Observe na imagem acima que a exceção: **FormatException**  (indicado pela seta rosa), foi disparada, mas desta vez foi exibida uma mensagem personalizada de alerta sobre o erro (indicada pela seta amarela). Como implementamos o bloco **finally**, também será exibida a mensagem criada dentro do bloco (indicada pela seta azul) e o programa será reiniciado (seta verde), solicitando uma nova entrada de dados. 

Experimente inserir os valores 10 e 2:

<div align="center"><img src="https://i.imgur.com/zwPcMKQ.png" title="source: imgur.com" /></div>

Observe na imagem acima que nenhuma exceção foi disparada e o cálculo da divisão foi efetuado com sucesso. Entretanto, como implementamos o comando **finally**, a mensagem (indicada pela seta verde) continuará sendo exibida, mesmo que nenhuma exceção seja disparada.

<br />

<div align="left"><img src="https://i.imgur.com/DNV9Rxu.png" title="source: imgur.com" width="25px"/> <a href="https://learn.microsoft.com/pt-br/dotnet/csharp/fundamentals/exceptions/" target="_blank"><b>Documentação: Exceptions</b></a></div>

<div align="left"><img src="https://i.imgur.com/DNV9Rxu.png" title="source: imgur.com" width="25px"/> <a href="https://learn.microsoft.com/pt-br/dotnet/csharp/language-reference/statements/exception-handling-statements#the-try-statement" target="_blank"><b>Documentação: try catch finally</b></a></div>

<div align="left"><img src="https://i.imgur.com/DNV9Rxu.png" title="source: imgur.com" width="25px"/> <a href="https://learn.microsoft.com/pt-br/dotnet/api/system.dividebyzeroexception?view=net-7.0" target="_blank"><b>Documentação: DivideByZeroException</b></a></div>

<div align="left"><img src="https://i.imgur.com/DNV9Rxu.png" title="source: imgur.com" width="25px"/> <a href="https://learn.microsoft.com/pt-br/dotnet/api/system.formatexception?view=net-7.0" target="_blank"><b>Documentação: FormatException</b></a></div>

<br />

<div align="left"><img src="https://i.imgur.com/JACNZiR.png" title="source: imgur.com" width="25px"/> <a href="" target="_blank"><b>Código fonte: Exemplo 02</b></a></div>

<br />

<h2>3. A Classe Exceptions</h2>

Como vimos no exemplo anterior, foram tratadas 2 Exceções dentro da aplicação: **DivideByZeroException** **FormatException**. De onde vieram estas Exceções? a resposta é a Classe **Exceptions**, que é uma Sub-Classe da Classe **System**. Veja na imagem abaixo, a hierarquia da Classe Exception:

<div align="center"><img src="https://i.imgur.com/Lrv1qbY.png" title="source: imgur.com" /></div>

- **System:** São as classes que lançam exceções comuns do sistema. **Exemplo:** tentar dividir um número por zero. 
- **Data Exception**: São exceções que indicam erros de Banco de dados. **Exemplo:** tentar duplicar a Chave Primária. 
- **IOException**: São exceções que indicam erros de entrada/saída por falha ou interrupção. **Exemplo:** interrupção ou falha na leitura de um arquivo em disco.
- **Application Exception**: São exceções criadas pela pessoa desenvolvedora para responder a um erro específico do sistema.

<h3>3.1. Exceções Integradas</h3>

As exceções integradas são as exceções disponíveis nas bibliotecas C#. Essas exceções são adequadas para explicar certas situações de erro. Na tabela abaixo, listamos as Exceções mais tratadas:

| Tipo de exceção                                              | Descrição                                                    |
| ------------------------------------------------------------ | ------------------------------------------------------------ |
| [Exception](https://learn.microsoft.com/pt-br/dotnet/api/system.exception) | A classe base para todas as exceções.                        |
| [IndexOutOfRangeException](https://learn.microsoft.com/pt-br/dotnet/api/system.indexoutofrangeexception) | Gerada pelo runtime somente quando uma matriz é indexada incorretamente. |
| [NullReferenceException](https://learn.microsoft.com/pt-br/dotnet/api/system.nullreferenceexception) | Gerada pelo runtime somente quando um objeto nulo é referenciado. |
| [InvalidOperationException](https://learn.microsoft.com/pt-br/dotnet/api/system.invalidoperationexception) | Gerada por métodos quando em um estado inválido.             |
| [ArgumentException](https://learn.microsoft.com/pt-br/dotnet/api/system.argumentexception) | A classe base para todas as exceções de argumento.           |
| [ArgumentNullException](https://learn.microsoft.com/pt-br/dotnet/api/system.argumentnullexception) | Gerada por métodos que não permitem que um argumento seja nulo. |
| [ArgumentOutOfRangeException](https://learn.microsoft.com/pt-br/dotnet/api/system.argumentoutofrangeexception) | Gerada por métodos que verificam se os argumentos estão em um determinado intervalo. |
| [ArithmeticException](https://learn.microsoft.com/pt-br/dotnet/api/system.arithmeticexception) | Uma classe base para exceções que ocorrem durante operações aritméticas. |
| [ArrayTypeMismatchException](https://learn.microsoft.com/pt-br/dotnet/api/system.arraytypemismatchexception) | Gerada quando uma matriz não pode armazenar determinado elemento  porque o tipo real do elemento é incompatível com o tipo real da matriz. |
| [DivideByZeroException](https://learn.microsoft.com/pt-br/dotnet/api/system.dividebyzeroexception) | Lançada quando é feita uma tentativa de dividir um valor inteiro por zero. |
| [IndexOutOfRangeException](https://learn.microsoft.com/pt-br/dotnet/api/system.indexoutofrangeexception) | Lançada quando é feita uma tentativa de indexar uma matriz quando o índice é menor que zero ou fora dos limites da matriz. |
| [InvalidCastException](https://learn.microsoft.com/pt-br/dotnet/api/system.invalidcastexception) | Gerada quando uma conversão explícita de um tipo base para uma interface ou um tipo derivado falha em tempo de execução. |
| [NullReferenceException](https://learn.microsoft.com/pt-br/dotnet/api/system.nullreferenceexception) | Gerada quando há uma tentativa de fazer referência a um objeto cujo valor é [null](https://learn.microsoft.com/pt-br/dotnet/csharp/language-reference/keywords/null). |
| [OutOfMemoryException](https://learn.microsoft.com/pt-br/dotnet/api/system.outofmemoryexception) | Lançada quando uma tentativa de alocar memória usando o operador [new](https://learn.microsoft.com/pt-br/dotnet/csharp/language-reference/operators/new-operator) falha. Essa exceção indica que a memória disponível para o Common Language Runtime está esgotada. |
| [OverflowException](https://learn.microsoft.com/pt-br/dotnet/api/system.overflowexception) | Lançada quando uma operação aritmética em um contexto `checked` estoura. |
| [StackOverflowException](https://learn.microsoft.com/pt-br/dotnet/api/system.stackoverflowexception) | Lançada quando a pilha de execução acaba tendo muitas chamadas de  método pendentes, normalmente indica uma recursão muito profunda ou  infinita. |
| [TypeInitializationException](https://learn.microsoft.com/pt-br/dotnet/api/system.typeinitializationexception) | Lançada quando um construtor estático lança uma exceção e não há nenhuma cláusula `catch` compatível para capturá-la. |

<br />

<div align="left"><img src="https://i.imgur.com/DNV9Rxu.png" title="source: imgur.com" width="30px"/> <a href="https://www.completecsharptutorial.com/basic/complete-system-exception.php" target="_blank"><b>Artigo: Lista Completa de Exceções da Linguagem C#</b></a></div>

<br />


<h2>4. Throw</h2>

A **Cláusula throw lança uma exceção em qualquer ponto do código**, mas não exige que ela seja tratada pela Classe que está chamando o Método. Ela transfere o controle do fluxo para os métodos chamadores. A cláusula throw permite lançar exceções verificadas ou não verificadas.

A palavra-chave throw é usada principalmente para lançar exceções personalizadas, ou seja, uma Classe de Exceção criada pela pessoa desenvolvedora, para ser lançada em um erro específico, quando o C# não possui um tipo de Exceção Integrada adequado para o erro. Veja o exemplo abaixo:

<br />

<div align="left"><img src="https://i.imgur.com/DNV9Rxu.png" title="source: imgur.com" width="30px"/> <a href="https://learn.microsoft.com/pt-br/dotnet/csharp/language-reference/statements/exception-handling-statements#the-throw-statement" target="_blank"><b>Documentação: throw</b></a></div>

<br />

<img src="https://i.imgur.com/bm8Jxxm.png" title="source: imgur.com" width="4%"/>**Exemplo 03 - Cláusula Throw - Versão 01:** 

No exemplo abaixo, vamos construir uma aplicação para checar se uma pessoa está apta a dirigir:

```c#
namespace exceptions_03
{
    internal class Program
    {
        static void Main(string[] args)
        {
            int idade;

            Console.WriteLine("\nDigite uma idade: ");
            idade = Convert.ToInt32(Console.ReadLine());

            ValidarIdade(idade);
        }

        public static void ValidarIdade(int idade)
        {

            if (idade < 18)
                throw new ArithmeticException("A Pessoa não pode dirigir!!");
            else
                Console.WriteLine("A Pessoa pode dirigir!!");

        }
    }
}
```

Execute o código acima e digite um valor menor do que 18 anos. O resultado você confere abaixo:

<img src="https://i.imgur.com/V2ReOnx.png" title="source: imgur.com" width="3%"/>**Resultado do Algoritmo:**

```bash
Digite uma idade:
12
Unhandled exception. System.ArithmeticException: A Pessoa não pode dirigir!!
   at exceptions_03.Program.ValidarIdade(Int32 idade) in C:\Users\rafae\OneDrive\Área de Trabalho\csharp\cookbook\16_exceptions\exceptions_03\Program.cs:line 19
   at exceptions_03.Program.Main(String[] args) in C:\Users\rafae\OneDrive\Área de Trabalho\csharp\cookbook\16_exceptions\exceptions_03\Program.cs:line 12
```

<br />

Observe que a exceção: **ArithmeticException**  foi disparada dentro do Método **ValidarIdade()**, exibindo a mensagem padrão do erro e o programa foi finalizado imediatamente.

Ao executar a instrução **throw**, o programa tenta encontrar algum bloco **try**, que possua instrução **catch** correspondente ao tipo de exceção que foi lançada. Se encontrar uma correspondência, o controle será transferido para essa instrução, caso contrário o programa será finalizado. Vamos atualizar este código inserindo um Bloco **try...catch**.

<br />

<div align="left"><img src="https://i.imgur.com/JACNZiR.png" title="source: imgur.com" width="25px"/> <a href="https://github.com/rafaelq80/exemplos_java/tree/main/exceptions/exceptions_throw_v1" target="_blank"><b>Código fonte: Exemplo 03</b></a></div>

<br />

<img src="https://i.imgur.com/bm8Jxxm.png" title="source: imgur.com" width="4%"/>**Exemplo 04 - Cláusula Throw - Versão 2:** 

```c#
namespace exceptions_04
{
    internal class Program
    {
        static void Main(string[] args)
        {
            int idade;
            bool loop = true;

            do
            {

                try
                {

                    Console.WriteLine("\nDigite uma idade: ");
                    idade = Convert.ToInt32(Console.ReadLine());

                    ValidarIdade(idade);

                    loop = false;

                }
                catch (ArithmeticException)
                {
                    Console.WriteLine("\nDigite um número inteiro maior ou igual a 18!");
                }

            } while (loop);
        }

        public static void ValidarIdade(int idade)
        {

            if (idade < 18)
                throw new ArithmeticException("A Pessoa não pode dirigir!!");
            else
                Console.WriteLine("A Pessoa pode dirigir!!");

        }
    }
}
```

Execute o código acima e digite um valor menor do que 18 anos. O resultado você confere abaixo:

<img src="https://i.imgur.com/V2ReOnx.png" title="source: imgur.com" width="3%"/>**Resultado do Algoritmo:**

```bash
Digite uma idade: 
12

Digite um número inteiro maior ou igual a 18!

Digite uma idade:_ 
```

<br />

Observe que a exceção: **ArithmeticException** foi disparada dentro do Método **ValidarIdade()**, mas desta vez foi exibida a mensagem personalizada: *"Digite um número inteiro maior ou igual a 18!"*. Além disso, o controle sobre o que fazer com o erro, foi transferido para o Bloco **try...catch**, que solicita ao usuário que digite uma nova idade maior ou igual a 18. Como foi implementado um Laço de repetição **do...while**, este processo se repetirá até que o usuário digite uma idade maior ou igual a 18.

<br />

<div align="left"><img src="https://i.imgur.com/JACNZiR.png" title="source: imgur.com" width="25px"/> <a href="" target="_blank"><b>Código fonte: Exemplo 04</b></a></div>

<br />

<h2>4. Exceções definidas pelo usuário</h2>



Exceções definidas pelo usuário são aquelas exceções que não são definidas pela linguagem de programação. Em C#, podemos criar nossas próprias exceções personalizadas para tratar erros específicos da aplicação.

As exceções C# são definidas como classes, assim como qualquer outro objeto C#. Todas as exceções são herdadas de uma classe base System.Exception. Há muitas exceções comuns que você pode usar em seu próprio código, como vimos anteriormente.

Criar suas próprias exceções personalizadas em C# é útil apenas quando você  for capturar um tipo específico de exceção e manipulá-lo de maneira diferente .Veja o exemplo abaixo:

<br />

<img src="https://i.imgur.com/bm8Jxxm.png" title="source: imgur.com" width="4%"/>**Exemplo 05 - Exceção personalizada** 

1. Criar um novo projeto chamado **excecaosimples**;
2. Inserir a **Classe ExcecaoSimples** (Exceção personalizada), que será uma Classe do tipo Exception, criada pela pessoa desenvolvedora;
3. Inserir o código abaixo na Classe **ExcecaoSimples**:

```c#
using System;
using System.Collections.Generic;
using System.Linq;
using System.Text;
using System.Threading.Tasks;

namespace excecao_simples
{
    public class ExcecaoSimples : Exception
    {
        public ExcecaoSimples(string message) : base(message)
        {
            Console.WriteLine("Exceção definida pelo Usuário!");
        }
    }
}

```

Observe que a Classe **ExcecaoSimples** foi definida como uma herança da Classe **Exception**.

> **Herança** é um tipo de Relacionamento entre Classes no C# e uma das maiores vantagens da Programação Orientada a Objetos, permitindo que o código seja reutilizado. Em C#, é possível herdar **atributos** e **comportamentos** (**métodos**) de uma classe para outra. A palavra extends inserida na assinatura da Classe, indica que a Classe está herdando uma outra Classe.

Na sequência, foi criado 1 Método Construtor, herdado da Classe Exception com o parâmetro **message**, que permite personalizar a mensagem de erro. A Classe Exception possui outros Métodos Construtores com outros parâmetros, que podem ser utilizados conforme a sua necessidade.

<br />

<div align="left"><img src="https://i.imgur.com/DNV9Rxu.png" title="source: imgur.com" width="30px"/> <a href="https://learn.microsoft.com/pt-br/dotnet/standard/exceptions/how-to-create-localized-exception-messages" target="_blank"><b>Documentação: Exceções definidas pelo usuário</b></a></div>

<br />


Na sequência, vamos testar a nossa Classe **ExcecaoSimples** inserindo o código abaixo na **Classe Program**:

```c#
namespace excecao_simples
{
    internal class Program
    {
        static void Main(string[] args)
        {
            string[] nomes = { "João", "Maria", "Pedro", "Manuela" };

            try
            {
                for (int i = 0; i < nomes.Length; i++)
                {
                    Console.WriteLine(nomes[i]);
                }
            }
            catch (IndexOutOfRangeException e)
            {
                Console.Error.WriteLine("\nExceção: " + e);
                Console.WriteLine("\nPosição Inválida");
            }

            throw new ExcecaoSimples("Exceção Simples Lançada!");

        }
    }
}
```

Observe que foi inserido no final do código a linha **throw new ExcecaoSimples("Exceção Simples!")**. Nesta linha, estamos lançando a exceção criada na **Classe ExcecaoSimples**, independente ter acontecido um erro, ou seja, ela será lançada de qualquer forma. Veja o resultado no console abaixo:

<img src="https://i.imgur.com/V2ReOnx.png" title="source: imgur.com" width="3%"/>**Resultado do Algoritmo:**

```bash
João
Maria
Pedro
Manuela
Exceção definida pelo Usuário!
Unhandled exception. excecao_simples.ExcecaoSimples: Exceção Simples Lançada!
   at excecao_simples.Program.Main(String[] args) in C:\Users\rafae\OneDrive\Área de Trabalho\csharp\cookbook\16_exceptions\excecao_simples\Program.cs:line 22
```

Observe que mesmo a Exception **IndexOutOfRangeException** não sendo disparada, a Exception ExceçãoSimples foi disparada. Este recurso é útil quando queremos lançar uma exceção em um condicional, por exemplo, caso uma condição não seja satisfeita.

<br />

<div align="left"><img src="https://i.imgur.com/JACNZiR.png" title="source: imgur.com" width="25px"/> <a href="" target="_blank"><b>Código fonte: Exemplo 05</b></a></div>

<br />

<h2>5. Por que devemos tratar as Exceções?</h2>

Quando uma Exceção é tratada, estamos oferecendo alguma forma alternativa para continuar a execução do programa sem que ele seja finalizado devido ao erro. O tratamento de exceções desempenha um papel importante no desenvolvimento de uma aplicação concisa, limpa, legível e de fácil manutenção. 

<br />

------

## 🔑**Pontos chave:**

1. **Exceções** em C# são classes especiais utilizadas para manipular erros que podem surgir durante a execução.
2. *O* **bloco try/catch/finally** permite capturar exceções que podem ocorrer quando uma parcela de código ou função é executada.
3. A **cláusula throw lança uma exceção em qualquer ponto do código**, mas não exige que ela seja tratada por seus chamadores.
5. Você também pode criar e lançar exceções personalizadas.

<br /><br />

<div align="left"><a href="README.md"><img src="https://i.imgur.com/XMgF3gl.png" title="source: imgur.com" width="3%"/>Voltar</a></div>
